<?xml version="1.0"?>
<robot xmlns:xacro="http://ros.org/wiki/xacro" name="simple_robot_drive">

<!-- =============================== BASE PLATE LINK =============================== -->
  
<!-- This is the central, structural part of the robot. All other components are attached to it. -->
  
  <link name="base_link">
    <visual>
      <origin rpy="0 0 0" xyz="0 0 0.05"/>
      <geometry>
        <box size="0.3 0.2 0.01"/>
      </geometry>
      <material name="blue">
        <color rgba="0.0 0.0 0.8 1.0"/>
      </material>
    </visual>
    <collision>
      <origin rpy="0 0 0" xyz="0 0 0.05"/>
      <geometry>
        <box size="0.3 0.2 0.01"/>
      </geometry>
    </collision>
    <inertial>
      <origin rpy="0 0 0" xyz="0 0 0.05"/>
      <mass value="1.0"/>
      <inertia ixx="0.01" ixy="0.0" ixz="0.0" iyy="0.01" iyz="0.0" izz="0.01"/>
    </inertial>
  </link>
  
<!-- =============================== LEFT WHEEL LINK & JOINT =============================== -->
  
  <joint name="left_wheel_joint" type="continuous">
    <parent link="base_link"/>
    <child link="left_wheel_link"/>
    <origin xyz="0.12 -0.11 0.05" rpy="1.570796 0 0"/>
    <axis xyz="0 0 1"/>
  </joint>
  <link name="left_wheel_link">
    <visual>
      <origin rpy="0 0 0" xyz="0 0 0"/>
      <geometry>
        <cylinder radius="0.05" length="0.04"/>
      </geometry>
      <material name="red">
        <color rgba="0.8 0.0 0.0 1.0"/>
      </material>
    </visual>
    <collision>
      <origin rpy="0 0 0" xyz="0 0 0"/>
      <geometry>
        <cylinder radius="0.05" length="0.04"/>
      </geometry>
    </collision>
    <inertial>
      <origin rpy="0 0 0" xyz="0 0 0"/>
      <mass value="0.5"/>
      <inertia ixx="0.001" ixy="0.0" ixz="0.0" iyy="0.001" iyz="0.0" izz="0.001"/>
    </inertial>
  </link>
  
<!-- =============================== RIGHT WHEEL LINK & JOINT =============================== -->
  
  <joint name="right_wheel_joint" type="continuous">
    <parent link="base_link"/>
    <child link="right_wheel_link"/>
    <origin xyz="0.12 0.11 0.05" rpy="1.570796 0 0"/>
    <axis xyz="0 0 1"/>
  </joint>
  <link name="right_wheel_link">
    <visual>
      <origin rpy="0 0 0" xyz="0 0 0"/>
      <geometry>
        <cylinder radius="0.05" length="0.04"/>
      </geometry>
      <material name="red"/>
    </visual>
    <collision>
      <origin rpy="0 0 0" xyz="0 0 0"/>
      <geometry>
        <cylinder radius="0.05" length="0.04"/>
      </geometry>
    </collision>
    <inertial>
      <origin rpy="0 0 0" xyz="0 0 0"/>
      <mass value="0.5"/>
      <inertia ixx="0.001" ixy="0.0" ixz="0.0" iyy="0.001" iyz="0.0" izz="0.001"/>
    </inertial>
  </link>
  
<!-- =============================== CASTER WHEEL LINK & JOINT =============================== -->
  
    <joint name="caster_joint" type="fixed">
    <parent link="base_link"/>
    <child link="caster_link"/>
    <origin xyz="-0.12 0 0.025" rpy="0 0 0"/>
  </joint>
  <link name="caster_link">
    <visual>
      <origin rpy="0 0 0" xyz="0 0 0"/>
      <geometry>
        <sphere radius="0.025"/>
      </geometry>
      <material name="black">
        <color rgba="0.1 0.1 0.1 1.0"/>
      </material>
    </visual>
    <collision>
      <origin rpy="0 0 0" xyz="0 0 0"/>
      <geometry>
        <sphere radius="0.025"/>
      </geometry>
    </collision>
    <inertial>
      <origin rpy="0 0 0" xyz="0 0 0"/>
      <mass value="0.1"/>
      <inertia ixx="0.0001" ixy="0.0" ixz="0.0" iyy="0.0001" iyz="0.0" izz="0.0001"/>
    </inertial>
  </link>
  
<!-- =============================== SENSOR LINK & JOINT =============================== -->
  
  <joint name="sensor_joint" type="fixed">
    <parent link="base_link"/>
    <child link="sensor_link"/>
    <origin xyz="0.15 0 0.06" rpy="0 0 0"/>
  </joint>
  <link name="sensor_link">
    <visual>
      <origin rpy="0 0 0" xyz="0 0 0"/>
      <geometry>
        <box size="0.03 0.05 0.02"/>
      </geometry>
      <material name="green">
        <color rgba="0.0 0.8 0.0 1.0"/>
      </material>
    </visual>
    <collision>
      <origin rpy="0 0 0" xyz="0 0 0"/>
      <geometry>
        <box size="0.03 0.05 0.02"/>
      </geometry>
    </collision>
    <inertial>
      <origin rpy="0 0 0" xyz="0 0 0"/>
      <mass value="0.05"/>
      <inertia ixx="0.00001" ixy="0.0" ixz="0.0" iyy="0.00001" iyz="0.0" izz="0.00001"/>
    </inertial>
  </link>

<!-- ============================= TRANSMISSION TAGS ============================= -->

<!-- These link the joints to actuators in the control system. -->

<transmission name="left_wheel_trans">
  <type>transmission_interface/SimpleTransmission</type>
  <joint name="left_wheel_joint">
    <hardwareInterface>hardware_interface/Velocity</hardwareInterface>
  </joint>
  <actuator name="left_wheel_motor">
    <hardwareInterface>hardware_interface/Velocity</hardwareInterface>
    <mechanicalReduction>1</mechanicalReduction>
  </actuator>
</transmission>

<transmission name="right_wheel_trans">
  <type>transmission_interface/SimpleTransmission</type>
  <joint name="right_wheel_joint">
    <hardwareInterface>hardware_interface/Velocity</hardwareInterface>
  </joint>
  <actuator name="right_wheel_motor">
    <hardwareInterface>hardware_interface/Velocity</hardwareInterface>
    <mechanicalReduction>1</mechanicalReduction>
  </actuator>
</transmission>


<!-- ============================= GAZEBO TAGS ============================= -->

<!-- This is the single, combined Gazebo block required by the parser. -->

<gazebo>
  <plugin name="gazebo_ros2_control" filename="libgazebo_ros2_control.so">
    <robot_param>robot_description</robot_param>
    <robot_param_node>robot_state_publisher</robot_param_node>
    <parameters>$(find simple_robot_description)/config/controllers.yaml</parameters>
  </plugin>
</gazebo>

<gazebo reference="base_link">
  <material>Gazebo/Blue</material>
</gazebo>

<gazebo reference="left_wheel_link">
  <material>Gazebo/Red</material>
</gazebo>

<gazebo reference="right_wheel_link">
  <material>Gazebo/Red</material>
</gazebo>

<gazebo reference="caster_link">
  <material>Gazebo/Black</material>
  <mu1>0.0</mu1>
  <mu2>0.0</mu2>
  <kp>1000000.0</kp>
  <kd>10.0</kd>
</gazebo>

<gazebo reference="sensor_link">
  <material>Gazebo/Green</material>
</gazebo>

<!-- ============================= ROS2 CONTROL BLOCK ============================= -->

<!-- This defines which joints are controlled by ros2_control and their interfaces. -->

<ros2_control name="simple_robot_system" type="system">
  <hardware>
    <plugin>gazebo_ros2_control/GazeboSystem</plugin>
  </hardware>

  <joint name="left_wheel_joint">
    <command_interface name="velocity"/>
    <state_interface name="position"/>
    <state_interface name="velocity"/>
  </joint>

  <joint name="right_wheel_joint">
    <command_interface name="velocity"/>
    <state_interface name="position"/>
    <state_interface name="velocity"/>
  </joint>
</ros2_control>

</robot>
